<?xml version="1.0"?>
<robot name="durian_bot" xmlns:xacro="http://ros.org/wiki/xacro">

  <link name="base_link">
    <visual>
      <geometry><box size="0.4 0.3 0.1"/></geometry>
      <material name="blue"><color rgba="0 0 1 1"/></material>
    </visual>
    <collision>
      <geometry><box size="0.4 0.3 0.1"/></geometry>
    </collision>
    <inertial>
      <mass value="5.0"/>
      <inertia ixx="0.04" ixy="0.0" ixz="0.0" iyy="0.07" iyz="0.0" izz="0.08"/>
    </inertial>
  </link>

  <link name="left_wheel">
    <visual><geometry><cylinder radius="0.05" length="0.02"/></geometry></visual>
    <collision><geometry><cylinder radius="0.05" length="0.02"/></geometry></collision>
    <inertial>
      <mass value="0.5"/><inertia ixx="0.0003" ixy="0.0" ixz="0.0" iyy="0.0003" iyz="0.0" izz="0.0006"/>
    </inertial>
  </link>
  <joint name="left_wheel_joint" type="continuous">
    <parent link="base_link"/><child link="left_wheel"/>
    <origin xyz="-0.1 0.15 0.0" rpy="-1.5708 0 0"/><axis xyz="0 0 1"/>
  </joint>

  <link name="right_wheel">
    <visual><geometry><cylinder radius="0.05" length="0.02"/></geometry></visual>
    <collision><geometry><cylinder radius="0.05" length="0.02"/></geometry></collision>
    <inertial>
      <mass value="0.5"/><inertia ixx="0.0003" ixy="0.0" ixz="0.0" iyy="0.0003" iyz="0.0" izz="0.0006"/>
    </inertial>
  </link>
  <joint name="right_wheel_joint" type="continuous">
    <parent link="base_link"/><child link="right_wheel"/>
    <origin xyz="-0.1 -0.15 0.0" rpy="-1.5708 0 0"/><axis xyz="0 0 1"/>
  </joint>

  <link name="laser">
    <visual><geometry><cylinder radius="0.05" length="0.04"/></geometry></visual>
    <collision><geometry><cylinder radius="0.05" length="0.04"/></geometry></collision>
  </link>
  <joint name="laser_joint" type="fixed">
    <parent link="base_link"/><child link="laser"/>
    <origin xyz="0.12 0.0 0.25" rpy="0 0 0"/>
  </joint>

  <link name="camera_link">
    <visual><geometry><box size="0.05 0.05 0.05"/></geometry></visual>
  </link>
  <joint name="camera_joint" type="fixed">
    <parent link="base_link"/><child link="camera_link"/>
    <origin xyz="0.18 0.0 0.2" rpy="0 0 0"/>
  </joint>

  <gazebo>
    <plugin name="diff_drive_controller" filename="libgazebo_ros_diff_drive.so">
      <update_rate>20</update_rate>
      <left_joint>left_wheel_joint</left_joint>
      <right_joint>right_wheel_joint</right_joint>
      <wheel_separation>0.3</wheel_separation>
      <wheel_diameter>0.1</wheel_diameter>
      <publish_odom>true</publish_odom>
      <publish_odom_tf>true</publish_odom_tf>
      <publish_wheel_tf>true</publish_wheel_tf>
      <odometry_frame>odom</odometry_frame>
      <robot_base_frame>base_link</robot_base_frame>
    </plugin>
    
    <plugin name="joint_state_publisher" filename="libgazebo_ros_joint_state_publisher.so">
      <update_rate>20</update_rate>
      <joint_name>left_wheel_joint</joint_name>
      <joint_name>right_wheel_joint</joint_name>
    </plugin>
  </gazebo>

  <gazebo reference="laser">
    <sensor name="lidar" type="ray">
      <always_on>true</always_on><visualize>true</visualize><update_rate>10</update_rate>
      <ray>
        <scan><horizontal><samples>360</samples><resolution>1</resolution><min_angle>-3.14</min_angle><max_angle>3.14</max_angle></horizontal></scan>
        <range><min>0.1</min><max>5.0</max><resolution>0.01</resolution></range>
      </ray>
      <plugin name="scan" filename="libgazebo_ros_ray_sensor.so">
        <ros><remapping>~/out:=scan</remapping></ros>
        <output_type>sensor_msgs/LaserScan</output_type>
        <frame_name>laser</frame_name>
      </plugin>
    </sensor>
  </gazebo>

  <gazebo reference="camera_link">
    <sensor name="camera_sensor" type="camera">
      <always_on>true</always_on><visualize>true</visualize><update_rate>15.0</update_rate>
      <camera>
        <horizontal_fov>1.047</horizontal_fov>
        <image><width>640</width><height>480</height><format>R8G8B8</format></image>
      </camera>
      <plugin name="camera_controller" filename="libgazebo_ros_camera.so">
        <frame_name>camera_link</frame_name>
      </plugin>
    </sensor>
  </gazebo>

</robot>