<?xml version="1.0"?>
<robot name="durian_bot" xmlns:xacro="http://ros.org/wiki/xacro">

  <link name="base_link">
    <visual>
      <geometry><box size="0.4 0.3 0.1"/></geometry>
      <material name="blue"><color rgba="0 0 1 1"/></material>
    </visual>
    <collision>
      <geometry><box size="0.4 0.3 0.1"/></geometry>
    </collision>
    <inertial>
       <mass value="5.0"/>
      <inertia ixx="0.015" ixy="0.0" ixz="0.0" iyy="0.027" iyz="0.0" izz="0.041"/>
    </inertial>
  </link>

  <link name="caster_wheel">
    <visual>
      <geometry><sphere radius="0.02"/></geometry>
    </visual>
    <collision>
      <geometry><sphere radius="0.02"/></geometry>
    </collision>
    <inertial>
      <mass value="0.1"/>
      <inertia ixx="0.00001" ixy="0.0" ixz="0.0" iyy="0.00001" iyz="0.0" izz="0.00001"/>
    </inertial>
  </link>

  <joint name="caster_joint" type="fixed">
    <parent link="base_link"/>
    <child link="caster_wheel"/>
    <origin xyz="0.15 0.0 -0.04" rpy="0 0 0"/>
  </joint>

  <link name="left_wheel">
    <visual><geometry><cylinder radius="0.05" length="0.02"/></geometry></visual>
    <collision><geometry><sphere radius="0.05"/></geometry></collision>
    <inertial>
      <mass value="1.0"/><inertia ixx="0.0003" ixy="0.0" ixz="0.0" iyy="0.0003" iyz="0.0" izz="0.0006"/>
    </inertial>
  </link>
  <joint name="left_wheel_joint" type="continuous">
    <parent link="base_link"/><child link="left_wheel"/>
    <origin xyz="0.0 0.18 -0.02" rpy="-1.5708 0 0"/>
    <axis xyz="0 0 1"/> 
  </joint>

  <link name="right_wheel">
    <visual><geometry><cylinder radius="0.05" length="0.02"/></geometry></visual>
    <collision><geometry><sphere radius="0.05"/></geometry></collision>
    <inertial>
      <mass value="1.0"/><inertia ixx="0.0003" ixy="0.0" ixz="0.0" iyy="0.0003" iyz="0.0" izz="0.0006"/>
    </inertial>
  </link>
  <joint name="right_wheel_joint" type="continuous">
    <parent link="base_link"/><child link="right_wheel"/>
    <origin xyz="0.0 -0.18 -0.02" rpy="-1.5708 0 0"/>
    <axis xyz="0 0 1"/>
  </joint>

  <link name="laser">
    <visual><geometry><cylinder radius="0.05" length="0.04"/></geometry></visual>
    <collision><geometry><cylinder radius="0.05" length="0.04"/></geometry></collision>
  </link>
  <joint name="laser_joint" type="fixed">
    <parent link="base_link"/><child link="laser"/>
    <origin xyz="0.12 0.0 0.26" rpy="0 0 0"/>
  </joint>

  <link name="camera_link">
    <visual><geometry><box size="0.05 0.05 0.05"/></geometry></visual>
  </link>
  <joint name="camera_joint" type="fixed">
    <parent link="base_link"/><child link="camera_link"/>
    <origin xyz="0.18 0.0 0.2" rpy="0 0 0"/>
  </joint>

  <gazebo>
    <plugin name="diff_drive_controller" filename="libgazebo_ros_diff_drive.so">
        <ros>
            <parameter name="use_sim_time" value="true"/>
            <remapping>cmd_vel:=cmd_vel</remapping>
            <remapping>odom:=odom</remapping>
        </ros>

        <wheel_separation>0.36</wheel_separation>
        <wheel_diameter>0.1</wheel_diameter>
        <max_wheel_acceleration>0.5</max_wheel_acceleration>
        <max_wheel_torque>20.0</max_wheel_torque>
        <left_joint>left_wheel_joint</left_joint>
        <right_joint>right_wheel_joint</right_joint>
        <update_rate>30.0</update_rate>
        <publish_odom>true</publish_odom>
        <publish_odom_tf>true</publish_odom_tf>
        <publish_wheel_tf>true</publish_wheel_tf> 
        <odometry_frame>odom</odometry_frame>
        <robot_base_frame>base_link</robot_base_frame>
    </plugin>
    
    </gazebo>

  <gazebo reference="laser">
  <sensor name="lidar" type="ray">
    <always_on>true</always_on>
    <visualize>true</visualize>
    <update_rate>10</update_rate>
    <ray>
      <scan>
        <horizontal>
          <samples>360</samples>
          <resolution>1</resolution>
          <min_angle>-3.14</min_angle>
          <max_angle>3.14</max_angle>
        </horizontal>
      </scan>
      <range>
        <min>0.15</min> <max>5.0</max>
        <resolution>0.01</resolution>
      </range>
    </ray>
    <plugin name="scan" filename="libgazebo_ros_ray_sensor.so">
      <ros>
          <remapping>~/out:=scan</remapping>
          <argument>--ros-args --param use_sim_time:=true</argument>
        </ros>
      <output_type>sensor_msgs/LaserScan</output_type>
      <frame_name>laser</frame_name>
    </plugin>
  </sensor>
</gazebo>

  <gazebo reference="camera_link">
    <sensor name="camera_sensor" type="camera">
      <always_on>true</always_on><visualize>true</visualize><update_rate>15.0</update_rate>
      <camera>
        <horizontal_fov>1.047</horizontal_fov>
        <image><width>640</width><height>480</height><format>R8G8B8</format></image>
      </camera>
      <plugin name="camera_controller" filename="libgazebo_ros_camera.so">
        <frame_name>camera_link</frame_name>
      </plugin>
    </sensor>
  </gazebo>

  <gazebo reference="base_link">
    <kp>1000000.0</kp>
    <kd>10.0</kd>
    <mu1>0.0</mu1>
    <mu2>0.0</mu2>
    <self_collide>false</self_collide> 
    <minDepth>0.01</minDepth> </gazebo>

  <gazebo reference="caster_wheel">
    <mu1>0.1</mu1>
    <mu2>0.1</mu2>
    <kp>1000000.0</kp>
    <kd>100.0</kd>
    <minDepth>0.01</minDepth>
  </gazebo>
 
  <gazebo reference="left_wheel">
    <mu1>100.0</mu1>
    <mu2>100.0</mu2>
    <kp>1000000.0</kp>
    <kd>10.0</kd>
    <minDepth>0.005</minDepth>
  </gazebo>

  <gazebo reference="right_wheel">
    <mu1>100.0</mu1>
    <mu2>100.0</mu2>
    <kp>1000000.0</kp>
    <kd>10.0</kd>
    <minDepth>0.005</minDepth>
  </gazebo>
</robot>